Traceback (most recent call last):
  File "/usr/local/lib/python3.9/site-packages/jupyter_cache/executors/utils.py", line 51, in single_nb_execution
    executenb(
  File "/usr/local/lib/python3.9/site-packages/nbclient/client.py", line 1093, in execute
    return NotebookClient(nb=nb, resources=resources, km=km, **kwargs).execute()
  File "/usr/local/lib/python3.9/site-packages/nbclient/util.py", line 84, in wrapped
    return just_run(coro(*args, **kwargs))
  File "/usr/local/lib/python3.9/site-packages/nbclient/util.py", line 62, in just_run
    return loop.run_until_complete(coro)
  File "/usr/local/Cellar/python@3.9/3.9.13/Frameworks/Python.framework/Versions/3.9/lib/python3.9/asyncio/base_events.py", line 647, in run_until_complete
    return future.result()
  File "/usr/local/lib/python3.9/site-packages/nbclient/client.py", line 559, in async_execute
    await self.async_execute_cell(
  File "/usr/local/lib/python3.9/site-packages/nbclient/client.py", line 854, in async_execute_cell
    self._check_raise_for_error(cell, exec_reply)
  File "/usr/local/lib/python3.9/site-packages/nbclient/client.py", line 756, in _check_raise_for_error
    raise CellExecutionError.from_cell_and_msg(cell, exec_reply_content)
nbclient.exceptions.CellExecutionError: An error occurred while executing the following cell:
------------------
from math import floor
from random import random
import numpy as np
import matplotlib.pyplot as plt

def tirage():
    d1=floor(6*random()+1)   
    d2=floor(6*random()+1)  
    return d1+d2 -1          

x = np.arange(0,12)
f = np.zeros(12)
n=10000                       
for i in range(n):        
    f[tirage() ] += 1
f=f/n     


plt.figure(figsize=(10,5))          
plt.subplot(121)
plt.plot( x, f, 'o' )   
plt.vlines( x, 0, f )   
plt.ylim( bottom=0 ) 
plt.title("Distribution")
fig,ax = plt.subplot(122)
plt.plot( x, f, 'o' )   
plt.vlines( x, 0, f )   
plt.ylim( bottom=0 ) 
plt.title("Fonction de r√©partition")
plt.show()
------------------

[0;31m---------------------------------------------------------------------------[0m
[0;31mTypeError[0m                                 Traceback (most recent call last)
Input [0;32mIn [2][0m, in [0;36m<module>[0;34m[0m
[1;32m     23[0m plt[38;5;241m.[39mylim( bottom[38;5;241m=[39m[38;5;241m0[39m ) 
[1;32m     24[0m plt[38;5;241m.[39mtitle([38;5;124m"[39m[38;5;124mDistribution[39m[38;5;124m"[39m)
[0;32m---> 25[0m fig,ax [38;5;241m=[39m plt[38;5;241m.[39msubplot([38;5;241m122[39m)
[1;32m     26[0m plt[38;5;241m.[39mplot( x, f, [38;5;124m'[39m[38;5;124mo[39m[38;5;124m'[39m )   
[1;32m     27[0m plt[38;5;241m.[39mvlines( x, [38;5;241m0[39m, f )   

[0;31mTypeError[0m: cannot unpack non-iterable AxesSubplot object
TypeError: cannot unpack non-iterable AxesSubplot object

