Traceback (most recent call last):
  File "/usr/local/lib/python3.9/site-packages/jupyter_cache/executors/utils.py", line 51, in single_nb_execution
    executenb(
  File "/usr/local/lib/python3.9/site-packages/nbclient/client.py", line 1093, in execute
    return NotebookClient(nb=nb, resources=resources, km=km, **kwargs).execute()
  File "/usr/local/lib/python3.9/site-packages/nbclient/util.py", line 84, in wrapped
    return just_run(coro(*args, **kwargs))
  File "/usr/local/lib/python3.9/site-packages/nbclient/util.py", line 62, in just_run
    return loop.run_until_complete(coro)
  File "/usr/local/Cellar/python@3.9/3.9.16/Frameworks/Python.framework/Versions/3.9/lib/python3.9/asyncio/base_events.py", line 647, in run_until_complete
    return future.result()
  File "/usr/local/lib/python3.9/site-packages/nbclient/client.py", line 559, in async_execute
    await self.async_execute_cell(
  File "/usr/local/lib/python3.9/site-packages/nbclient/client.py", line 854, in async_execute_cell
    self._check_raise_for_error(cell, exec_reply)
  File "/usr/local/lib/python3.9/site-packages/nbclient/client.py", line 756, in _check_raise_for_error
    raise CellExecutionError.from_cell_and_msg(cell, exec_reply_content)
nbclient.exceptions.CellExecutionError: An error occurred while executing the following cell:
------------------
import numpy as np
from  random  import  random
import random
import matplotlib.pyplot as plt

def experience(n):
    f = []
    for j in range(n):
        if random() <0.4:
            f += [1.]
        else:
            f+=[0]
        
    f = np.cumsum(f)
    for i in range(n):
        f[i] = float(f[i])/(i+1)
    return(f)

n = 100
plt.figure(figsize=(12,6))
x = np.arange(n)
for i in range(8):
    f = experience(n)
    plt.plot(x,f)
    plt.xlabel('$n$')
    plt.ylabel('$f_n$')
plt.axhline(y = 0.4, color = 'k', linestyle = '--')

plt.tight_layout()
------------------

[0;31m---------------------------------------------------------------------------[0m
[0;31mTypeError[0m                                 Traceback (most recent call last)
Input [0;32mIn [1][0m, in [0;36m<module>[0;34m[0m
[1;32m     21[0m x [38;5;241m=[39m np[38;5;241m.[39marange(n)
[1;32m     22[0m [38;5;28;01mfor[39;00m i [38;5;129;01min[39;00m [38;5;28mrange[39m([38;5;241m8[39m):
[0;32m---> 23[0m     f [38;5;241m=[39m [43mexperience[49m[43m([49m[43mn[49m[43m)[49m
[1;32m     24[0m     plt[38;5;241m.[39mplot(x,f)
[1;32m     25[0m     plt[38;5;241m.[39mxlabel([38;5;124m'[39m[38;5;124m$n$[39m[38;5;124m'[39m)

Input [0;32mIn [1][0m, in [0;36mexperience[0;34m(n)[0m
[1;32m      7[0m f [38;5;241m=[39m []
[1;32m      8[0m [38;5;28;01mfor[39;00m j [38;5;129;01min[39;00m [38;5;28mrange[39m(n):
[0;32m----> 9[0m     [38;5;28;01mif[39;00m [43mrandom[49m[43m([49m[43m)[49m [38;5;241m<[39m[38;5;241m0.4[39m:
[1;32m     10[0m         f [38;5;241m+[39m[38;5;241m=[39m [[38;5;241m1.[39m]
[1;32m     11[0m     [38;5;28;01melse[39;00m:

[0;31mTypeError[0m: 'module' object is not callable
TypeError: 'module' object is not callable

