Traceback (most recent call last):
  File "/Users/vibarra/Venv/lib/python3.9/site-packages/jupyter_cache/executors/utils.py", line 58, in single_nb_execution
    executenb(
  File "/Users/vibarra/Venv/lib/python3.9/site-packages/nbclient/client.py", line 1314, in execute
    return NotebookClient(nb=nb, resources=resources, km=km, **kwargs).execute()
  File "/Users/vibarra/Venv/lib/python3.9/site-packages/jupyter_core/utils/__init__.py", line 165, in wrapped
    return loop.run_until_complete(inner)
  File "/opt/homebrew/Cellar/python@3.9/3.9.21/Frameworks/Python.framework/Versions/3.9/lib/python3.9/asyncio/base_events.py", line 647, in run_until_complete
    return future.result()
  File "/Users/vibarra/Venv/lib/python3.9/site-packages/nbclient/client.py", line 709, in async_execute
    await self.async_execute_cell(
  File "/Users/vibarra/Venv/lib/python3.9/site-packages/nbclient/client.py", line 1062, in async_execute_cell
    await self._check_raise_for_error(cell, cell_index, exec_reply)
  File "/Users/vibarra/Venv/lib/python3.9/site-packages/nbclient/client.py", line 918, in _check_raise_for_error
    raise CellExecutionError.from_cell_and_msg(cell, exec_reply_content)
nbclient.exceptions.CellExecutionError: An error occurred while executing the following cell:
------------------
alpha = 0.05
t_c = st.t.ppf([alpha/2,1-alpha/2], df=len(x)-2)
print('l'intervalle de tc est  ' + str(np.round(t_c,2)))
print('et la t-value est ' + str(round(b1/std_err,2)))
------------------


[0;36m  Cell [0;32mIn[6], line 3[0;36m[0m
[0;31m    print('l'intervalle de tc est  ' + str(np.round(t_c,2)))[0m
[0m             ^[0m
[0;31mSyntaxError[0m[0;31m:[0m invalid syntax


